Workbook

Sheet README
A1: CRITICAL SUPPLIER PERFORMANCE REVIEW — REVAMPED WORKBOOK
A2: Remediation & Restructuring Q1 2026 → Template Reusable untuk Q2 2026
A4: 1. APA YANG BERUBAH DARI FILE ASLI
A5: • 18 sheet per-supplier (ITSEC, IPROTEKSI, dst) dengan angka HARDCODE dikonsolidasikan menjadi 1 sheet SCORE CALC — semua nilai sekarang formula, ditarik LANGSUNG dari RAW DATA, tidak ada lagi copy-paste manual.
A6: • Sheet CONFIG baru ditambahkan: berisi mapping kolom (Quality/Timeline/Relationship) per supplier ke RAW DATA. Ini yang membuat file REUSABLE — untuk Q2, cukup update kolom 'Raw Sheet Name' di CONFIG dan tempel data baru, seluruh perhitungan otomatis mengikuti.
A7: • Sheet RESULT dirombak: Total Score, Status, Remarks, dan DD Result (by User) sekarang 100% formula (live link ke raw data). Kolom 'Assessment Result (by SRM)' dan 'Repetition of Below Expectation' tetap manual input (kuning) karena butuh judgement SRM, bukan hasil kalkulasi.
A8: • Sheet SUMMARY diperbaiki: '% Vendor Dievaluasi' sebelumnya menampilkan angka mentah (1) alih-alih persentase — sekarang benar (0%-100%) dan berbasis formula, bukan hitung manual.
A9: • Sheet HISTORICAL: kolom skor Q1 2026 sekarang live-link ke RESULT (bukan angka mati), dan status (Meet/Exceed/dst) memakai formula ambang batas yang SAMA dengan kolom tahun-tahun sebelumnya (sebelumnya kolom Q1 2026 di-ketik manual, tidak konsisten dengan formula tahun lalu).
A10: • Sheet 'Sheet1' (draft yang tidak terpakai, cuma 1 baris) dihapus.
A12: 2. BUG YANG DITEMUKAN & DIPERBAIKI (PENTING)
A13: Saat formula lama diganti dengan link otomatis ke raw data, ditemukan 3 kesalahan formula di file asli:
A14: a) Satria Antaran Prima – Mailing Room: formula Timeline ("=AVERAGE(I3:P3)*35%") salah rentang — ikut merata-ratakan kolom Quality & hasil weighted Quality (M3) alih-alih hanya kolom Timeline (N:P). Total Score resmi 3.063272 → seharusnya 3.404167. Status TETAP 'Meet Expectation', tidak berubah.
... A39: Score <= 1.9 → Unsatisfactory

Sheet CONFIG
A1: No | B1: Supplier & Service (Key) | C1: PIC Email | D1: Raw Sheet Name (Quarter Aktif) | E1: Quality Col Start | F1: Quality Col End | G1: Timeline Col Start | H1: Timeline Col End | I1: Relationship Col Start | J1: Relationship Col End | K1: Remarks Col | L1: Financial Assessment Col | M1: Reputational Col | N1: DPIA Required Col | O1: DPSQ Required Col | P1: VSDDT Required Col | Q1: Action Plan Col
A2: 1 | B2: Itsec Asia - Penetration Testing | C2: fauzi.aryanto@axa-mandiri.co.id | D2: RAW DATA Q1 - 1 | E2: FJ | F2: FL | G2: FN | H2: FP | I2: GH | J2: GJ | K2: GS | L2: GK | M2: GL | N2: GM | O2: GN | P2: GO | Q2: GQ
A3: 2 | B3: Iproteksi Telematika - Penetration Testing | C3: fauzi.aryanto@axa-mandiri.co.id | D3: RAW DATA Q1 - 1 | E3: FG | F3: FI | G3: FN | H3: FP | I3: GH | J3: GJ | K3: GS | L3: GK | M3: GL | N3: GM | O3: GN | P3: GO | Q3: GQ
A4: 3 | B4: FPT Metrodata - Penetration Testing | C4: fauzi.aryanto@axa-mandiri.co.id | D4: RAW DATA Q1 - 1 | E4: FD | F4: FF | G4: FN | H4: FP | I4: GH | J4: GJ | K4: GS | L4: GK | M4: GL | N4: GM | O4: GN | P4: GO | Q4: GQ
A5: 4 | B5: Satria Antaran Prima - Mailing Room | C5: ibnu.kumala@axa-mandiri.co.id | D5: RAW DATA Q1 - 1 | E5: DX | F5: EE | G5: FN | H5: FP | I5: GH | J5: GJ | K5: GS | L5: GK | M5: GL | N5: GM | O5: GN | P5: GO | Q5: GQ
A6: 5 | B6: Informasi Teknologi Indonesia - SMS Broadcast | C6: fifin.sarinurlita@axa-mandiri.co.id | D6: RAW DATA Q1 - 1 | E6: AA | F6: AK | G6: FO | H6: FS | I6: GH | J6: GJ | K6: GS | L6: GK | M6: GL | N6: GM | O6: GN | P6: GO | Q6: GQ
A7: 6 | B7: Satria Antaran Prima - Courier Service | C7: fifin.sarinurlita@axa-mandiri.co.id | D7: RAW DATA Q1 - 1 | E7: DI | F7: DW | G7: GE | H7: GG | I7: GH | J7: GJ | K7: GS | L7: GK | M7: GL | N7: GM | O7: GN | P7: GO | Q7: GQ
A8: 7 | B8: Multifiling Mitra Indonesia - Record Management Service | C8: ibnu.kumala@axa-mandiri.co.id | D8: RAW DATA Q1 - 1 | E8: AY | F8: BI | G8: FU | H8: FX | I8: GH | J8: GJ | K8: GS | L8: GK | M8: GL | N8: GM | O8: GN | P8: GO | Q8: GQ
A9: 8 | B9: Indosat - Layanan PBX berbasiskan cloud dengan Teknologi SIP Trunk | C9: nuril.hudha@axa-mandiri.co.id | D9: RAW DATA Q1 - 1 | E9: G | F9: Z | G9: FN | H9: FP | I9: GH | J9: GJ | K9: GS | L9: GK | M9: GL | N9: GM | O9: GN | P9: GO | Q9: GQ
A10: 9 | B10: Ciptadra Softindo - Pemeliharaan Axits & DMTM | C10: raninta.mahardi@axa-mandiri.co.id | D10: RAW DATA Q1 - 1 | E10: BJ | F10: BW | G10: FY | H10: GD | I10: GH | J10: GJ | K10: GS | L10: GK | M10: GL | N10: GM | O10: GN | P10: GO | Q10: GQ
A11: 10 | B11: Target Sukses Sinergi - Email Marketing Automation | C11: bella.depari@axa-mandiri.co.id | D11: RAW DATA Q1 - 1 | E11: EF | F11: EL | G11: FN | H11: FP | I11: GH | J11: GJ | K11: GS | L11: GK | M11: GL | N11: GM | O11: GN | P11: GO | Q11: GQ
A12: 11 | B12: Inmotion Inovasi Teknologi - Jasa Aplikasi Chatbot dan Live Chat | C12: djoko.djoko@axa-mandiri.co.id | D12: RAW DATA Q1 - 1 | E12: BX | F12: DH | G12: FN | H12: FP | I12: GH | J12: GJ | K12: GS | L12: GK | M12: GL | N12: GM | O12: GN | P12: GO | Q12: GQ
A13: 12 | B13: Mitra Integrasi Informatika - SFDC Maintenance | C13: chandra.putra@axa-mandiri.co.id | D13: RAW DATA Q1 - 1 | E13: AL | F13: AX | G13: FN | H13: FP | I13: GH | J13: GJ | K13: GS | L13: GK | M13: GL | N13: GM | O13: GN | P13: GO | Q13: GQ
... A19: 18 | B19: Karya Putra Surya Gemilang - Telemarketing Revamp Project | C19: reza.resdilana@axa-mandiri.co.id | D19: RAW DATA Q1 - 2 | E19: O | F19: Y | G19: CJ | H19: CL | I19: CS | J19: CU | K19: DF | L19: CV | M19: CW | N19: CX | O19: CZ | P19: DB | Q19: DD

Sheet SCORE CALC
A1: No | B1: Supplier & Service | C1: Match Row (helper) | D1: Quality Avg (35%) | E1: Timeline Avg (35%) | F1: Relationship Avg (30%) | G1: TOTAL SCORE | H1: STATUS
A2: =CONFIG!A2 -> 1 | B2: =CONFIG!B2 -> Itsec Asia - Penetration Testing | C2: =MATCH($B2,INDIRECT("'"&CONFIG!D2&"'!$F:$F"),0) -> 2 | D2: =AVERAGE(INDIRECT("'"&CONFIG!D2&"'!"&CONFIG!E2&$C2&":"&CONFIG!F2&$C2)) -> 3 | E2: =AVERAGE(INDIRECT("'"&CONFIG!D2&"'!"&CONFIG!G2&$C2&":"&CONFIG!H2&$C2)) -> 3 | F2: =AVERAGE(INDIRECT("'"&CONFIG!D2&"'!"&CONFIG!I2&$C2&":"&CONFIG!J2&$C2)) -> 3 | G2: =D2*0.35+E2*0.35+F2*0.3 -> 3 | H2: =IF(G2>4.99,"Exceptional",IF(G2>3.99,"Exceed Expectation",IF(G2>=2.99,"Meet Expectation",IF(G2>1.9,"Below Expectation","Unsatisfactory")))) -> Meet Expectation
A3: =CONFIG!A3 -> 2 | B3: =CONFIG!B3 -> Iproteksi Telematika - Penetration Testing | C3: =MATCH($B3,INDIRECT("'"&CONFIG!D3&"'!$F:$F"),0) -> 3 | D3: =AVERAGE(INDIRECT("'"&CONFIG!D3&"'!"&CONFIG!E3&$C3&":"&CONFIG!F3&$C3)) -> 4 | E3: =AVERAGE(INDIRECT("'"&CONFIG!D3&"'!"&CONFIG!G3&$C3&":"&CONFIG!H3&$C3)) -> 4 | F3: =AVERAGE(INDIRECT("'"&CONFIG!D3&"'!"&CONFIG!I3&$C3&":"&CONFIG!J3&$C3)) -> 4 | G3: =D3*0.35+E3*0.35+F3*0.3 -> 4 | H3: =IF(G3>4.99,"Exceptional",IF(G3>3.99,"Exceed Expectation",IF(G3>=2.99,"Meet Expectation",IF(G3>1.9,"Below Expectation","Unsatisfactory")))) -> Exceed Expectation
A4: =CONFIG!A4 -> 3 | B4: =CONFIG!B4 -> FPT Metrodata - Penetration Testing | C4: =MATCH($B4,INDIRECT("'"&CONFIG!D4&"'!$F:$F"),0) -> 4 | D4: =AVERAGE(INDIRECT("'"&CONFIG!D4&"'!"&CONFIG!E4&$C4&":"&CONFIG!F4&$C4)) -> 3 | E4: =AVERAGE(INDIRECT("'"&CONFIG!D4&"'!"&CONFIG!G4&$C4&":"&CONFIG!H4&$C4)) -> 3 | F4: =AVERAGE(INDIRECT("'"&CONFIG!D4&"'!"&CONFIG!I4&$C4&":"&CONFIG!J4&$C4)) -> 3 | G4: =D4*0.35+E4*0.35+F4*0.3 -> 3 | H4: =IF(G4>4.99,"Exceptional",IF(G4>3.99,"Exceed Expectation",IF(G4>=2.99,"Meet Expectation",IF(G4>1.9,"Below Expectation","Unsatisfactory")))) -> Meet Expectation
A5: =CONFIG!A5 -> 4 | B5: =CONFIG!B5 -> Satria Antaran Prima - Mailing Room | C5: =MATCH($B5,INDIRECT("'"&CONFIG!D5&"'!$F:$F"),0) -> 5 | D5: =AVERAGE(INDIRECT("'"&CONFIG!D5&"'!"&CONFIG!E5&$C5&":"&CONFIG!F5&$C5)) -> 3.25 | E5: =AVERAGE(INDIRECT("'"&CONFIG!D5&"'!"&CONFIG!G5&$C5&":"&CONFIG!H5&$C5)) -> 3.3333333 | F5: =AVERAGE(INDIRECT("'"&CONFIG!D5&"'!"&CONFIG!I5&$C5&":"&CONFIG!J5&$C5)) -> 3.6666667 | G5: =D5*0.35+E5*0.35+F5*0.3 -> 3.4041667 | H5: =IF(G5>4.99,"Exceptional",IF(G5>3.99,"Exceed Expectation",IF(G5>=2.99,"Meet Expectation",IF(G5>1.9,"Below Expectation","Unsatisfactory")))) -> Meet Expectation
A6: =CONFIG!A6 -> 5 | B6: =CONFIG!B6 -> Informasi Teknologi Indonesia - SMS Broadcast | C6: =MATCH($B6,INDIRECT("'"&CONFIG!D6&"'!$F:$F"),0) -> 6 | D6: =AVERAGE(INDIRECT("'"&CONFIG!D6&"'!"&CONFIG!E6&$C6&":"&CONFIG!F6&$C6)) -> 3 | E6: =AVERAGE(INDIRECT("'"&CONFIG!D6&"'!"&CONFIG!G6&$C6&":"&CONFIG!H6&$C6)) -> 3 | F6: =AVERAGE(INDIRECT("'"&CONFIG!D6&"'!"&CONFIG!I6&$C6&":"&CONFIG!J6&$C6)) -> 3 | G6: =D6*0.35+E6*0.35+F6*0.3 -> 3 | H6: =IF(G6>4.99,"Exceptional",IF(G6>3.99,"Exceed Expectation",IF(G6>=2.99,"Meet Expectation",IF(G6>1.9,"Below Expectation","Unsatisfactory")))) -> Meet Expectation
A7: =CONFIG!A7 -> 6 | B7: =CONFIG!B7 -> Satria Antaran Prima - Courier Service | C7: =MATCH($B7,INDIRECT("'"&CONFIG!D7&"'!$F:$F"),0) -> 7 | D7: =AVERAGE(INDIRECT("'"&CONFIG!D7&"'!"&CONFIG!E7&$C7&":"&CONFIG!F7&$C7)) -> 3 | E7: =AVERAGE(INDIRECT("'"&CONFIG!D7&"'!"&CONFIG!G7&$C7&":"&CONFIG!H7&$C7)) -> 3 | F7: =AVERAGE(INDIRECT("'"&CONFIG!D7&"'!"&CONFIG!I7&$C7&":"&CONFIG!J7&$C7)) -> 3 | G7: =D7*0.35+E7*0.35+F7*0.3 -> 3 | H7: =IF(G7>4.99,"Exceptional",IF(G7>3.99,"Exceed Expectation",IF(G7>=2.99,"Meet Expectation",IF(G7>1.9,"Below Expectation","Unsatisfactory")))) -> Meet Expectation
A8: =CONFIG!A8 -> 7 | B8: =CONFIG!B8 -> Multifiling Mitra Indonesia - Record Management Service | C8: =MATCH($B8,INDIRECT("'"&CONFIG!D8&"'!$F:$F"),0) -> 8 | D8: =AVERAGE(INDIRECT("'"&CONFIG!D8&"'!"&CONFIG!E8&$C8&":"&CONFIG!F8&$C8)) -> 3.0909091 | E8: =AVERAGE(INDIRECT("'"&CONFIG!D8&"'!"&CONFIG!G8&$C8&":"&CONFIG!H8&$C8)) -> 3 | F8: =AVERAGE(INDIRECT("'"&CONFIG!D8&"'!"&CONFIG!I8&$C8&":"&CONFIG!J8&$C8)) -> 3 | G8: =D8*0.35+E8*0.35+F8*0.3 -> 3.0318182 | H8: =IF(G8>4.99,"Exceptional",IF(G8>3.99,"Exceed Expectation",IF(G8>=2.99,"Meet Expectation",IF(G8>1.9,"Below Expectation","Unsatisfactory")))) -> Meet Expectation
A9: =CONFIG!A9 -> 8 | B9: =CONFIG!B9 -> Indosat - Layanan PBX berbasiskan cloud dengan Teknologi SIP Trunk | C9: =MATCH($B9,INDIRECT("'"&CONFIG!D9&"'!$F:$F"),0) -> 9 | D9: =AVERAGE(INDIRECT("'"&CONFIG!D9&"'!"&CONFIG!E9&$C9&":"&CONFIG!F9&$C9)) -> 3.0526316 | E9: =AVERAGE(INDIRECT("'"&CONFIG!D9&"'!"&CONFIG!G9&$C9&":"&CONFIG!H9&$C9)) -> 3 | F9: =AVERAGE(INDIRECT("'"&CONFIG!D9&"'!"&CONFIG!I9&$C9&":"&CONFIG!J9&$C9)) -> 4 | G9: =D9*0.35+E9*0.35+F9*0.3 -> 3.3184211 | H9: =IF(G9>4.99,"Exceptional",IF(G9>3.99,"Exceed Expectation",IF(G9>=2.99,"Meet Expectation",IF(G9>1.9,"Below Expectation","Unsatisfactory")))) -> Meet Expectation
A10: =CONFIG!A10 -> 9 | B10: =CONFIG!B10 -> Ciptadra Softindo - Pemeliharaan Axits & DMTM | C10: =MATCH($B10,INDIRECT("'"&CONFIG!D10&"'!$F:$F"),0) -> 10 | D10: =AVERAGE(INDIRECT("'"&CONFIG!D10&"'!"&CONFIG!E10&$C10&":"&CONFIG!F10&$C10)) -> 4 | E10: =AVERAGE(INDIRECT("'"&CONFIG!D10&"'!"&CONFIG!G10&$C10&":"&CONFIG!H10&$C10)) -> 4 | F10: =AVERAGE(INDIRECT("'"&CONFIG!D10&"'!"&CONFIG!I10&$C10&":"&CONFIG!J10&$C10)) -> 4 | G10: =D10*0.35+E10*0.35+F10*0.3 -> 4 | H10: =IF(G10>4.99,"Exceptional",IF(G10>3.99,"Exceed Expectation",IF(G10>=2.99,"Meet Expectation",IF(G10>1.9,"Below Expectation","Unsatisfactory")))) -> Exceed Expectation
A11: =CONFIG!A11 -> 10 | B11: =CONFIG!B11 -> Target Sukses Sinergi - Email Marketing Automation | C11: =MATCH($B11,INDIRECT("'"&CONFIG!D11&"'!$F:$F"),0) -> 11 | D11: =AVERAGE(INDIRECT("'"&CONFIG!D11&"'!"&CONFIG!E11&$C11&":"&CONFIG!F11&$C11)) -> 3.7142857 | E11: =AVERAGE(INDIRECT("'"&CONFIG!D11&"'!"&CONFIG!G11&$C11&":"&CONFIG!H11&$C11)) -> 4 | F11: =AVERAGE(INDIRECT("'"&CONFIG!D11&"'!"&CONFIG!I11&$C11&":"&CONFIG!J11&$C11)) -> 4 | G11: =D11*0.35+E11*0.35+F11*0.3 -> 3.9 | H11: =IF(G11>4.99,"Exceptional",IF(G11>3.99,"Exceed Expectation",IF(G11>=2.99,"Meet Expectation",IF(G11>1.9,"Below Expectation","Unsatisfactory")))) -> Meet Expectation
A12: =CONFIG!A12 -> 11 | B12: =CONFIG!B12 -> Inmotion Inovasi Teknologi - Jasa Aplikasi Chatbot dan Live Chat | C12: =MATCH($B12,INDIRECT("'"&CONFIG!D12&"'!$F:$F"),0) -> 12 | D12: =AVERAGE(INDIRECT("'"&CONFIG!D12&"'!"&CONFIG!E12&$C12&":"&CONFIG!F12&$C12)) -> 4 | E12: =AVERAGE(INDIRECT("'"&CONFIG!D12&"'!"&CONFIG!G12&$C12&":"&CONFIG!H12&$C12)) -> 4 | F12: =AVERAGE(INDIRECT("'"&CONFIG!D12&"'!"&CONFIG!I12&$C12&":"&CONFIG!J12&$C12)) -> 4 | G12: =D12*0.35+E12*0.35+F12*0.3 -> 4 | H12: =IF(G12>4.99,"Exceptional",IF(G12>3.99,"Exceed Expectation",IF(G12>=2.99,"Meet Expectation",IF(G12>1.9,"Below Expectation","Unsatisfactory")))) -> Exceed Expectation
A13: =CONFIG!A13 -> 12 | B13: =CONFIG!B13 -> Mitra Integrasi Informatika - SFDC Maintenance | C13: =MATCH($B13,INDIRECT("'"&CONFIG!D13&"'!$F:$F"),0) -> 13 | D13: =AVERAGE(INDIRECT("'"&CONFIG!D13&"'!"&CONFIG!E13&$C13&":"&CONFIG!F13&$C13)) -> 4.8461538 | E13: =AVERAGE(INDIRECT("'"&CONFIG!D13&"'!"&CONFIG!G13&$C13&":"&CONFIG!H13&$C13)) -> 4.6666667 | F13: =AVERAGE(INDIRECT("'"&CONFIG!D13&"'!"&CONFIG!I13&$C13&":"&CONFIG!J13&$C13)) -> 5 | G13: =D13*0.35+E13*0.35+F13*0.3 -> 4.8294872 | H13: =IF(G13>4.99,"Exceptional",IF(G13>3.99,"Exceed Expectation",IF(G13>=2.99,"Meet Expectation",IF(G13>1.9,"Below Expectation","Unsatisfactory")))) -> Exceed Expectation
... A19: =CONFIG!A19 -> 18 | B19: =CONFIG!B19 -> Karya Putra Surya Gemilang - Telemarketing Revamp Project | C19: =MATCH($B19,INDIRECT("'"&CONFIG!D19&"'!$F:$F"),0) -> 7 | D19: =AVERAGE(INDIRECT("'"&CONFIG!D19&"'!"&CONFIG!E19&$C19&":"&CONFIG!F19&$C19)) -> 3.0909091 | E19: =AVERAGE(INDIRECT("'"&CONFIG!D19&"'!"&CONFIG!G19&$C19&":"&CONFIG!H19&$C19)) -> 3 | F19: =AVERAGE(INDIRECT("'"&CONFIG!D19&"'!"&CONFIG!I19&$C19&":"&CONFIG!J19&$C19)) -> 3 | G19: =D19*0.35+E19*0.35+F19*0.3 -> 3.0318182 | H19: =IF(G19>4.99,"Exceptional",IF(G19>3.99,"Exceed Expectation",IF(G19>=2.99,"Meet Expectation",IF(G19>1.9,"Below Expectation","Unsatisfactory")))) -> Meet Expectation

Sheet RESULT
A1: No | B1: Supplier Name | C1: Service | D1: PIC (User) | E1: Total Score | F1: Status | G1: Remarks (dari User) | H1: DD Result (by User) - Auto | I1: Assessment Result (by SRM) - Manual Input | J1: Repetition Below Expectation - Manual Input | K1: Helper: Below Expectation/Unsatisfactory Name
A2: ='SCORE CALC'!A2 -> 1 | B2: =TRIM(LEFT(CONFIG!B2,FIND(" - ",CONFIG!B2)-1)) -> Itsec Asia | C2: =TRIM(MID(CONFIG!B2,FIND(" - ",CONFIG!B2)+3,255)) -> Penetration Testing | D2: =CONFIG!C2 -> fauzi.aryanto@axa-mandiri.co.id | E2: ='SCORE CALC'!G2 -> 3 | F2: ='SCORE CALC'!H2 -> Meet Expectation | G2: =INDIRECT("'"&CONFIG!D2&"'!"&CONFIG!K2&'SCORE CALC'!C2) -> Currently no need improvement | H2: ="Financial Assessment: "&INDIRECT("'"&CONFIG!D2&"'!"&CONFIG!L2&'SCORE CALC'!C2)&CHAR(10)&"Reputational Assessment: "&INDIRECT("'"&CONFIG!D2&"'!"&CONFIG!M2&'SCORE CALC'!C2)&CHAR(10)&"DPIA: "&INDIRECT("'"&CONFIG!D2&"'!"&CONFIG!N2&'SCORE CALC'!C2)&CHAR(10)&"DPSQ: "&INDIRECT("'"&CONFIG!D2&"'!"&CONFIG!O2&'SCORE CALC'!C2)&CHAR(10)&"VSDDT: "&INDIRECT("'"&CONFIG!D2&"'!"&CONFIG!P2&'SCORE CALC'!C2)&CHAR(10)&"Action Plan: "&INDIRECT("'"&CONFIG!D2&"'!"&CONFIG!Q2&'SCORE CALC'!C2) -> Financial Assessment: Yes Reputational Assessment: Yes DPIA: Not required – DPIA is not applicable for this service DPSQ: Not required – DPSQ is not applicable for this service VSDDT: Required – VSDDT completed and approved Action Plan: Yes – All action items have been completed and coordinated with relevant SME | K2: =IF(OR(F2="Below Expectation",F2="Unsatisfactory"),B2&" - "&C2,"")
A3: ='SCORE CALC'!A3 -> 2 | B3: =TRIM(LEFT(CONFIG!B3,FIND(" - ",CONFIG!B3)-1)) -> Iproteksi Telematika | C3: =TRIM(MID(CONFIG!B3,FIND(" - ",CONFIG!B3)+3,255)) -> Penetration Testing | D3: =CONFIG!C3 -> fauzi.aryanto@axa-mandiri.co.id | E3: ='SCORE CALC'!G3 -> 4 | F3: ='SCORE CALC'!H3 -> Exceed Expectation | G3: =INDIRECT("'"&CONFIG!D3&"'!"&CONFIG!K3&'SCORE CALC'!C3) -> no need improvement | H3: ="Financial Assessment: "&INDIRECT("'"&CONFIG!D3&"'!"&CONFIG!L3&'SCORE CALC'!C3)&CHAR(10)&"Reputational Assessment: "&INDIRECT("'"&CONFIG!D3&"'!"&CONFIG!M3&'SCORE CALC'!C3)&CHAR(10)&"DPIA: "&INDIRECT("'"&CONFIG!D3&"'!"&CONFIG!N3&'SCORE CALC'!C3)&CHAR(10)&"DPSQ: "&INDIRECT("'"&CONFIG!D3&"'!"&CONFIG!O3&'SCORE CALC'!C3)&CHAR(10)&"VSDDT: "&INDIRECT("'"&CONFIG!D3&"'!"&CONFIG!P3&'SCORE CALC'!C3)&CHAR(10)&"Action Plan: "&INDIRECT("'"&CONFIG!D3&"'!"&CONFIG!Q3&'SCORE CALC'!C3) -> Financial Assessment: Yes Reputational Assessment: Yes DPIA: Not required – DPIA is not applicable for this service DPSQ: Not required – DPSQ is not applicable for this service VSDDT: Required – VSDDT completed and approved Action Plan: Yes – All action items have been completed and coordinated with relevant SME | K3: =IF(OR(F3="Below Expectation",F3="Unsatisfactory"),B3&" - "&C3,"")
A4: ='SCORE CALC'!A4 -> 3 | B4: =TRIM(LEFT(CONFIG!B4,FIND(" - ",CONFIG!B4)-1)) -> FPT Metrodata | C4: =TRIM(MID(CONFIG!B4,FIND(" - ",CONFIG!B4)+3,255)) -> Penetration Testing | D4: =CONFIG!C4 -> fauzi.aryanto@axa-mandiri.co.id | E4: ='SCORE CALC'!G4 -> 3 | F4: ='SCORE CALC'!H4 -> Meet Expectation | G4: =INDIRECT("'"&CONFIG!D4&"'!"&CONFIG!K4&'SCORE CALC'!C4) -> No need improvement | H4: ="Financial Assessment: "&INDIRECT("'"&CONFIG!D4&"'!"&CONFIG!L4&'SCORE CALC'!C4)&CHAR(10)&"Reputational Assessment: "&INDIRECT("'"&CONFIG!D4&"'!"&CONFIG!M4&'SCORE CALC'!C4)&CHAR(10)&"DPIA: "&INDIRECT("'"&CONFIG!D4&"'!"&CONFIG!N4&'SCORE CALC'!C4)&CHAR(10)&"DPSQ: "&INDIRECT("'"&CONFIG!D4&"'!"&CONFIG!O4&'SCORE CALC'!C4)&CHAR(10)&"VSDDT: "&INDIRECT("'"&CONFIG!D4&"'!"&CONFIG!P4&'SCORE CALC'!C4)&CHAR(10)&"Action Plan: "&INDIRECT("'"&CONFIG!D4&"'!"&CONFIG!Q4&'SCORE CALC'!C4) -> Financial Assessment: Yes Reputational Assessment: Yes DPIA: Not required – DPIA is not applicable for this service DPSQ: Not required – DPSQ is not applicable for this service VSDDT: Required – VSDDT completed and approved Action Plan: Yes – All action items have been completed and coordinated with relevant SME | K4: =IF(OR(F4="Below Expectation",F4="Unsatisfactory"),B4&" - "&C4,"")
A5: ='SCORE CALC'!A5 -> 4 | B5: =TRIM(LEFT(CONFIG!B5,FIND(" - ",CONFIG!B5)-1)) -> Satria Antaran Prima | C5: =TRIM(MID(CONFIG!B5,FIND(" - ",CONFIG!B5)+3,255)) -> Mailing Room | D5: =CONFIG!C5 -> ibnu.kumala@axa-mandiri.co.id | E5: ='SCORE CALC'!G5 -> 3.4041667 | F5: ='SCORE CALC'!H5 -> Meet Expectation | G5: =INDIRECT("'"&CONFIG!D5&"'!"&CONFIG!K5&'SCORE CALC'!C5) -> Over all mailing ok, please improve coordinated with Headoffice team for reduce complain/misscomm (ex case overseas shipment ) | H5: ="Financial Assessment: "&INDIRECT("'"&CONFIG!D5&"'!"&CONFIG!L5&'SCORE CALC'!C5)&CHAR(10)&"Reputational Assessment: "&INDIRECT("'"&CONFIG!D5&"'!"&CONFIG!M5&'SCORE CALC'!C5)&CHAR(10)&"DPIA: "&INDIRECT("'"&CONFIG!D5&"'!"&CONFIG!N5&'SCORE CALC'!C5)&CHAR(10)&"DPSQ: "&INDIRECT("'"&CONFIG!D5&"'!"&CONFIG!O5&'SCORE CALC'!C5)&CHAR(10)&"VSDDT: "&INDIRECT("'"&CONFIG!D5&"'!"&CONFIG!P5&'SCORE CALC'!C5)&CHAR(10)&"Action Plan: "&INDIRECT("'"&CONFIG!D5&"'!"&CONFIG!Q5&'SCORE CALC'!C5) -> Financial Assessment: Yes Reputational Assessment: Yes DPIA: Required – DPIA completed and approved DPSQ: Not required – DPSQ is not applicable for this service VSDDT: Required – VSDDT completed and approved Action Plan: Yes – All action items have been completed and coordinated with relevant SME | K5: =IF(OR(F5="Below Expectation",F5="Unsatisfactory"),B5&" - "&C5,"")
A6: ='SCORE CALC'!A6 -> 5 | B6: =TRIM(LEFT(CONFIG!B6,FIND(" - ",CONFIG!B6)-1)) -> Informasi Teknologi Indonesia | C6: =TRIM(MID(CONFIG!B6,FIND(" - ",CONFIG!B6)+3,255)) -> SMS Broadcast | D6: =CONFIG!C6 -> fifin.sarinurlita@axa-mandiri.co.id | E6: ='SCORE CALC'!G6 -> 3 | F6: ='SCORE CALC'!H6 -> Meet Expectation | G6: =INDIRECT("'"&CONFIG!D6&"'!"&CONFIG!K6&'SCORE CALC'!C6) -> Jatis has provided good service throughout this year | H6: ="Financial Assessment: "&INDIRECT("'"&CONFIG!D6&"'!"&CONFIG!L6&'SCORE CALC'!C6)&CHAR(10)&"Reputational Assessment: "&INDIRECT("'"&CONFIG!D6&"'!"&CONFIG!M6&'SCORE CALC'!C6)&CHAR(10)&"DPIA: "&INDIRECT("'"&CONFIG!D6&"'!"&CONFIG!N6&'SCORE CALC'!C6)&CHAR(10)&"DPSQ: "&INDIRECT("'"&CONFIG!D6&"'!"&CONFIG!O6&'SCORE CALC'!C6)&CHAR(10)&"VSDDT: "&INDIRECT("'"&CONFIG!D6&"'!"&CONFIG!P6&'SCORE CALC'!C6)&CHAR(10)&"Action Plan: "&INDIRECT("'"&CONFIG!D6&"'!"&CONFIG!Q6&'SCORE CALC'!C6) -> Financial Assessment: Yes Reputational Assessment: Yes DPIA: Required – DPIA completed and approved DPSQ: Required – DPSQ completed and approved VSDDT: Required – VSDDT completed and approved Action Plan: No – No action items were required | K6: =IF(OR(F6="Below Expectation",F6="Unsatisfactory"),B6&" - "&C6,"")
A7: ='SCORE CALC'!A7 -> 6 | B7: =TRIM(LEFT(CONFIG!B7,FIND(" - ",CONFIG!B7)-1)) -> Satria Antaran Prima | C7: =TRIM(MID(CONFIG!B7,FIND(" - ",CONFIG!B7)+3,255)) -> Courier Service | D7: =CONFIG!C7 -> fifin.sarinurlita@axa-mandiri.co.id | E7: ='SCORE CALC'!G7 -> 3 | F7: ='SCORE CALC'!H7 -> Meet Expectation | G7: =INDIRECT("'"&CONFIG!D7&"'!"&CONFIG!K7&'SCORE CALC'!C7) -> SAP has provided excellent service throughout this year | H7: ="Financial Assessment: "&INDIRECT("'"&CONFIG!D7&"'!"&CONFIG!L7&'SCORE CALC'!C7)&CHAR(10)&"Reputational Assessment: "&INDIRECT("'"&CONFIG!D7&"'!"&CONFIG!M7&'SCORE CALC'!C7)&CHAR(10)&"DPIA: "&INDIRECT("'"&CONFIG!D7&"'!"&CONFIG!N7&'SCORE CALC'!C7)&CHAR(10)&"DPSQ: "&INDIRECT("'"&CONFIG!D7&"'!"&CONFIG!O7&'SCORE CALC'!C7)&CHAR(10)&"VSDDT: "&INDIRECT("'"&CONFIG!D7&"'!"&CONFIG!P7&'SCORE CALC'!C7)&CHAR(10)&"Action Plan: "&INDIRECT("'"&CONFIG!D7&"'!"&CONFIG!Q7&'SCORE CALC'!C7) -> Financial Assessment: Yes Reputational Assessment: Yes DPIA: Required – DPIA completed and approved DPSQ: Required – DPSQ completed and approved VSDDT: Required – VSDDT completed and approved Action Plan: Yes – Action items identified, but follow‑up and coordination with relevant SME is still required | K7: =IF(OR(F7="Below Expectation",F7="Unsatisfactory"),B7&" - "&C7,"")
A8: ='SCORE CALC'!A8 -> 7 | B8: =TRIM(LEFT(CONFIG!B8,FIND(" - ",CONFIG!B8)-1)) -> Multifiling Mitra Indonesia | C8: =TRIM(MID(CONFIG!B8,FIND(" - ",CONFIG!B8)+3,255)) -> Record Management Service | D8: =CONFIG!C8 -> ibnu.kumala@axa-mandiri.co.id | E8: ='SCORE CALC'!G8 -> 3.0318182 | F8: ='SCORE CALC'!H8 -> Meet Expectation | G8: =INDIRECT("'"&CONFIG!D8&"'!"&CONFIG!K8&'SCORE CALC'!C8) -> impprove innovation dan simplyfy process | H8: ="Financial Assessment: "&INDIRECT("'"&CONFIG!D8&"'!"&CONFIG!L8&'SCORE CALC'!C8)&CHAR(10)&"Reputational Assessment: "&INDIRECT("'"&CONFIG!D8&"'!"&CONFIG!M8&'SCORE CALC'!C8)&CHAR(10)&"DPIA: "&INDIRECT("'"&CONFIG!D8&"'!"&CONFIG!N8&'SCORE CALC'!C8)&CHAR(10)&"DPSQ: "&INDIRECT("'"&CONFIG!D8&"'!"&CONFIG!O8&'SCORE CALC'!C8)&CHAR(10)&"VSDDT: "&INDIRECT("'"&CONFIG!D8&"'!"&CONFIG!P8&'SCORE CALC'!C8)&CHAR(10)&"Action Plan: "&INDIRECT("'"&CONFIG!D8&"'!"&CONFIG!Q8&'SCORE CALC'!C8) -> Financial Assessment: Yes Reputational Assessment: Yes DPIA: Required – DPIA completed and approved DPSQ: Required – DPSQ completed and approved VSDDT: Required – VSDDT completed and approved Action Plan: Yes – All action items have been completed and coordinated with relevant SME | K8: =IF(OR(F8="Below Expectation",F8="Unsatisfactory"),B8&" - "&C8,"")
A9: ='SCORE CALC'!A9 -> 8 | B9: =TRIM(LEFT(CONFIG!B9,FIND(" - ",CONFIG!B9)-1)) -> Indosat | C9: =TRIM(MID(CONFIG!B9,FIND(" - ",CONFIG!B9)+3,255)) -> Layanan PBX berbasiskan cloud dengan Teknologi SIP Trunk | D9: =CONFIG!C9 -> nuril.hudha@axa-mandiri.co.id | E9: ='SCORE CALC'!G9 -> 3.3184211 | F9: ='SCORE CALC'!H9 -> Meet Expectation | G9: =INDIRECT("'"&CONFIG!D9&"'!"&CONFIG!K9&'SCORE CALC'!C9) -> The performance is getting better, please keep improve the performance. | H9: ="Financial Assessment: "&INDIRECT("'"&CONFIG!D9&"'!"&CONFIG!L9&'SCORE CALC'!C9)&CHAR(10)&"Reputational Assessment: "&INDIRECT("'"&CONFIG!D9&"'!"&CONFIG!M9&'SCORE CALC'!C9)&CHAR(10)&"DPIA: "&INDIRECT("'"&CONFIG!D9&"'!"&CONFIG!N9&'SCORE CALC'!C9)&CHAR(10)&"DPSQ: "&INDIRECT("'"&CONFIG!D9&"'!"&CONFIG!O9&'SCORE CALC'!C9)&CHAR(10)&"VSDDT: "&INDIRECT("'"&CONFIG!D9&"'!"&CONFIG!P9&'SCORE CALC'!C9)&CHAR(10)&"Action Plan: "&INDIRECT("'"&CONFIG!D9&"'!"&CONFIG!Q9&'SCORE CALC'!C9) -> Financial Assessment: No Reputational Assessment: Yes DPIA: Required – DPIA completed and approved DPSQ: Not required – DPSQ is not applicable for this service VSDDT: Required – VSDDT completed and approved Action Plan: Yes – Action items identified, but follow‑up and coordination with relevant SME is still required | K9: =IF(OR(F9="Below Expectation",F9="Unsatisfactory"),B9&" - "&C9,"")
A10: ='SCORE CALC'!A10 -> 9 | B10: =TRIM(LEFT(CONFIG!B10,FIND(" - ",CONFIG!B10)-1)) -> Ciptadra Softindo | C10: =TRIM(MID(CONFIG!B10,FIND(" - ",CONFIG!B10)+3,255)) -> Pemeliharaan Axits & DMTM | D10: =CONFIG!C10 -> raninta.mahardi@axa-mandiri.co.id | E10: ='SCORE CALC'!G10 -> 4 | F10: ='SCORE CALC'!H10 -> Exceed Expectation | G10: =INDIRECT("'"&CONFIG!D10&"'!"&CONFIG!K10&'SCORE CALC'!C10) -> Performance is Good | H10: ="Financial Assessment: "&INDIRECT("'"&CONFIG!D10&"'!"&CONFIG!L10&'SCORE CALC'!C10)&CHAR(10)&"Reputational Assessment: "&INDIRECT("'"&CONFIG!D10&"'!"&CONFIG!M10&'SCORE CALC'!C10)&CHAR(10)&"DPIA: "&INDIRECT("'"&CONFIG!D10&"'!"&CONFIG!N10&'SCORE CALC'!C10)&CHAR(10)&"DPSQ: "&INDIRECT("'"&CONFIG!D10&"'!"&CONFIG!O10&'SCORE CALC'!C10)&CHAR(10)&"VSDDT: "&INDIRECT("'"&CONFIG!D10&"'!"&CONFIG!P10&'SCORE CALC'!C10)&CHAR(10)&"Action Plan: "&INDIRECT("'"&CONFIG!D10&"'!"&CONFIG!Q10&'SCORE CALC'!C10) -> Financial Assessment: Yes Reputational Assessment: Yes DPIA: Required – DPIA completed and approved DPSQ: Required – DPSQ completed and approved VSDDT: Required – VSDDT completed and approved Action Plan: Yes – All action items have been completed and coordinated with relevant SME | K10: =IF(OR(F10="Below Expectation",F10="Unsatisfactory"),B10&" - "&C10,"")
A11: ='SCORE CALC'!A11 -> 10 | B11: =TRIM(LEFT(CONFIG!B11,FIND(" - ",CONFIG!B11)-1)) -> Target Sukses Sinergi | C11: =TRIM(MID(CONFIG!B11,FIND(" - ",CONFIG!B11)+3,255)) -> Email Marketing Automation | D11: =CONFIG!C11 -> bella.depari@axa-mandiri.co.id | E11: ='SCORE CALC'!G11 -> 3.9 | F11: ='SCORE CALC'!H11 -> Meet Expectation | G11: =INDIRECT("'"&CONFIG!D11&"'!"&CONFIG!K11&'SCORE CALC'!C11) -> Harganya buat next contrac please murahin ya | H11: ="Financial Assessment: "&INDIRECT("'"&CONFIG!D11&"'!"&CONFIG!L11&'SCORE CALC'!C11)&CHAR(10)&"Reputational Assessment: "&INDIRECT("'"&CONFIG!D11&"'!"&CONFIG!M11&'SCORE CALC'!C11)&CHAR(10)&"DPIA: "&INDIRECT("'"&CONFIG!D11&"'!"&CONFIG!N11&'SCORE CALC'!C11)&CHAR(10)&"DPSQ: "&INDIRECT("'"&CONFIG!D11&"'!"&CONFIG!O11&'SCORE CALC'!C11)&CHAR(10)&"VSDDT: "&INDIRECT("'"&CONFIG!D11&"'!"&CONFIG!P11&'SCORE CALC'!C11)&CHAR(10)&"Action Plan: "&INDIRECT("'"&CONFIG!D11&"'!"&CONFIG!Q11&'SCORE CALC'!C11) -> Financial Assessment: Yes Reputational Assessment: Yes DPIA: Required – DPIA completed and approved DPSQ: Required – DPSQ completed and approved VSDDT: Required – VSDDT completed and approved Action Plan: Yes – All action items have been completed and coordinated with relevant SME | K11: =IF(OR(F11="Below Expectation",F11="Unsatisfactory"),B11&" - "&C11,"")
A12: ='SCORE CALC'!A12 -> 11 | B12: =TRIM(LEFT(CONFIG!B12,FIND(" - ",CONFIG!B12)-1)) -> Inmotion Inovasi Teknologi | C12: =TRIM(MID(CONFIG!B12,FIND(" - ",CONFIG!B12)+3,255)) -> Jasa Aplikasi Chatbot dan Live Chat | D12: =CONFIG!C12 -> djoko.djoko@axa-mandiri.co.id | E12: ='SCORE CALC'!G12 -> 4 | F12: ='SCORE CALC'!H12 -> Exceed Expectation | G12: =INDIRECT("'"&CONFIG!D12&"'!"&CONFIG!K12&'SCORE CALC'!C12) -> continue performing thorough and frequent periodic checks to ensure that during service hours, there are no issues that could disrupt operations and resolve the remaining unresolved 401 issue Berikan umpan balik Anda tentang BizChat | H12: ="Financial Assessment: "&INDIRECT("'"&CONFIG!D12&"'!"&CONFIG!L12&'SCORE CALC'!C12)&CHAR(10)&"Reputational Assessment: "&INDIRECT("'"&CONFIG!D12&"'!"&CONFIG!M12&'SCORE CALC'!C12)&CHAR(10)&"DPIA: "&INDIRECT("'"&CONFIG!D12&"'!"&CONFIG!N12&'SCORE CALC'!C12)&CHAR(10)&"DPSQ: "&INDIRECT("'"&CONFIG!D12&"'!"&CONFIG!O12&'SCORE CALC'!C12)&CHAR(10)&"VSDDT: "&INDIRECT("'"&CONFIG!D12&"'!"&CONFIG!P12&'SCORE CALC'!C12)&CHAR(10)&"Action Plan: "&INDIRECT("'"&CONFIG!D12&"'!"&CONFIG!Q12&'SCORE CALC'!C12) -> Financial Assessment: Yes Reputational Assessment: Yes DPIA: Required – DPIA completed and approved DPSQ: Required – DPSQ not yet completed or approved VSDDT: Required – VSDDT completed and approved Action Plan: Yes – All action items have been completed and coordinated with relevant SME | K12: =IF(OR(F12="Below Expectation",F12="Unsatisfactory"),B12&" - "&C12,"")
A13: ='SCORE CALC'!A13 -> 12 | B13: =TRIM(LEFT(CONFIG!B13,FIND(" - ",CONFIG!B13)-1)) -> Mitra Integrasi Informatika | C13: =TRIM(MID(CONFIG!B13,FIND(" - ",CONFIG!B13)+3,255)) -> SFDC Maintenance | D13: =CONFIG!C13 -> chandra.putra@axa-mandiri.co.id | E13: ='SCORE CALC'!G13 -> 4.8294872 | F13: ='SCORE CALC'!H13 -> Exceed Expectation | G13: =INDIRECT("'"&CONFIG!D13&"'!"&CONFIG!K13&'SCORE CALC'!C13) -> verall, the level of support has been satisfactory. The improvements carried out were highly effective, and several demands were consistent with the initial assessment and expectations. | H13: ="Financial Assessment: "&INDIRECT("'"&CONFIG!D13&"'!"&CONFIG!L13&'SCORE CALC'!C13)&CHAR(10)&"Reputational Assessment: "&INDIRECT("'"&CONFIG!D13&"'!"&CONFIG!M13&'SCORE CALC'!C13)&CHAR(10)&"DPIA: "&INDIRECT("'"&CONFIG!D13&"'!"&CONFIG!N13&'SCORE CALC'!C13)&CHAR(10)&"DPSQ: "&INDIRECT("'"&CONFIG!D13&"'!"&CONFIG!O13&'SCORE CALC'!C13)&CHAR(10)&"VSDDT: "&INDIRECT("'"&CONFIG!D13&"'!"&CONFIG!P13&'SCORE CALC'!C13)&CHAR(10)&"Action Plan: "&INDIRECT("'"&CONFIG!D13&"'!"&CONFIG!Q13&'SCORE CALC'!C13) -> Financial Assessment: No Reputational Assessment: No DPIA: Not required – DPIA is not applicable for this service DPSQ: Not required – DPSQ is not applicable for this service VSDDT: Required – VSDDT not yet completed or approved Action Plan: No – No action items were required | K13: =IF(OR(F13="Below Expectation",F13="Unsatisfactory"),B13&" - "&C13,"")
... A19: ='SCORE CALC'!A19 -> 18 | B19: =TRIM(LEFT(CONFIG!B19,FIND(" - ",CONFIG!B19)-1)) -> Karya Putra Surya Gemilang | C19: =TRIM(MID(CONFIG!B19,FIND(" - ",CONFIG!B19)+3,255)) -> Telemarketing Revamp Project | D19: =CONFIG!C19 -> reza.resdilana@axa-mandiri.co.id | E19: ='SCORE CALC'!G19 -> 3.0318182 | F19: ='SCORE CALC'!H19 -> Meet Expectation | G19: =INDIRECT("'"&CONFIG!D19&"'!"&CONFIG!K19&'SCORE CALC'!C19) -> Diharapkan untuk tim project yang diassign apabila CR sudah di signoff agar availibility dari resource ready | H19: ="Financial Assessment: "&INDIRECT("'"&CONFIG!D19&"'!"&CONFIG!L19&'SCORE CALC'!C19)&CHAR(10)&"Reputational Assessment: "&INDIRECT("'"&CONFIG!D19&"'!"&CONFIG!M19&'SCORE CALC'!C19)&CHAR(10)&"DPIA: "&INDIRECT("'"&CONFIG!D19&"'!"&CONFIG!N19&'SCORE CALC'!C19)&CHAR(10)&"DPSQ: "&INDIRECT("'"&CONFIG!D19&"'!"&CONFIG!O19&'SCORE CALC'!C19)&CHAR(10)&"VSDDT: "&INDIRECT("'"&CONFIG!D19&"'!"&CONFIG!P19&'SCORE CALC'!C19)&CHAR(10)&"Action Plan: "&INDIRECT("'"&CONFIG!D19&"'!"&CONFIG!Q19&'SCORE CALC'!C19) -> Financial Assessment: Yes Reputational Assessment: Yes DPIA: Required – DPIA completed and approved DPSQ: Required – DPSQ not yet completed or approved VSDDT: Required – VSDDT completed and approved Action Plan: Yes – All action items have been completed and coordinated with relevant SME | K19: =IF(OR(F19="Below Expectation",F19="Unsatisfactory"),B19&" - "&C19,"")

Sheet SUMMARY
A1: CRITICAL SUPPLIER PERFORMANCE REVIEW - SUMMARY
A2: Periode Review | B2: Q1 2026
A3: Jumlah Vendor Dievaluasi (dari RESULT) | B3: =COUNTA(RESULT!B2:B19) -> 18
A4: Total Vendor Kritis (Master List) - Input Manual | B4: 19
A5: % Vendor Dievaluasi | B5: =B3/B4 -> 0.94736842
A6: Jumlah "Meet / Exceed Expectation" | B6: =SUMPRODUCT(--(RESULT!F2:F19<>"Below Expectation"))-SUMPRODUCT(--(RESULT!F2:F19="Unsatisfactory")) -> 17
A7: Jumlah "Under Performance" (Below Expectation) | B7: =COUNTIF(RESULT!F2:F19,"Below Expectation")+COUNTIF(RESULT!F2:F19,"Unsatisfactory") -> 1
A8: Vendor Critical Below Expectation | B8: =_xlfn.TEXTJOIN(", ",TRUE(),RESULT!K2:K19) -> Arah Sejahtera Abadi - Perjanjian Sewa Menyewa

Sheet HISTORICAL
A1: Suppliers Name | B1: Service Scope | C1: 2024 | K1: 2025 | Y1: 2026
C2: Q1 | E2: Q2 | G2: Q3 | I2: Q4 | K2: Q1 | N2: Q2 | Q2: Q3 | T2: Repetition of Below Expectation | U2: Remarks | V2: Q4 | Y2: Q1
K3: Score | L3: User Comment | M3: Remarks | N3: Score | O3: User Comment | P3: Remarks | Q3: Score | R3: User Comment | S3: Remarks | V3: Score | W3: User Comment | X3: Remarks | Y3: Score | Z3: User Comment | AA3: Remarks
A4: INDOSAT | B4: LAYANAN PBX BERBASISKAN CLOUD DENGAN TEKNOLOGI SIP TRUNK | C4: 3 | D4: =IF(C4>4.99,"Exceptional",IF(C4>3.99,"Exceed Expectation",IF(C4>=2.99,"Meet Expectation",IF(C4>1.9,"Below Expectation","Unsatisfactory")))) -> Meet Expectation | E4: 3 | F4: =IF(E4>4.99,"Exceptional",IF(E4>3.99,"Exceed Expectation",IF(E4>=2.99,"Meet Expectation",IF(E4>1.9,"Below Expectation","Unsatisfactory")))) -> Meet Expectation | G4: 2.95 | H4: =IF(G4>4.99,"Exceptional",IF(G4>3.99,"Exceed Expectation",IF(G4>=2.99,"Meet Expectation",IF(G4>1.9,"Below Expectation","Unsatisfactory")))) -> Below Expectation | I4: 3 | J4: =IF(I4>4.99,"Exceptional",IF(I4>3.9,"Exceed Expectation",IF(I4>=2.99,"Meet Expectation",IF(I4>1.9,"Below Expectation","Unsatisfactory")))) -> Meet Expectation | K4: 2.345 | L4: Need improvement for the part of fair and to be more responsive to solve issues. | M4: =IF(K4>4.99,"Exceptional",IF(K4>3.9,"Exceed Expectation",IF(K4>=2.99,"Meet Expectation",IF(K4>1.9,"Below Expectation","Unsatisfactory")))) -> Below Expectation | N4: 1.99 | O4: 1. Dashboard access to required user 2. Response time to be improved as promised 3. To be more proactive in update the progress 4. To provide regular report (usage, recording, etc) | P4: =IF(N4>4.99,"Exceptional",IF(N4>3.9,"Exceed Expectation",IF(N4>=2.99,"Meet Expectation",IF(N4>1.9,"Below Expectation","Unsatisfactory")))) -> Below Expectation | Q4: 2.72 | R4: improve responsiveness when there is problem appear, and more proactive ask client follow up for the re-solution work or not after fixing. have plan maintenance and communicated earlier to client so client can aware about maintenance process. | S4: Below Expectation | T4: 3X | U4: Sudah dilakukan pemanggilan terhadap vendor yang bersangkutan dan pada Q3 terjadi perbaikan performance pada aspek kualitas jasa yang diberikan, dan pemenuhan timeline SLA | V4: 2.9825 | W4: PLEASE KINDLY IMPROVE REQUIRED REPORT DELIVERY AS AGREED WITH ANALYZED DATA FOR BUSINESS CONSIDERATION. | X4: BELOW EXPECTATION | Y4: =RESULT!E9 -> 3.3184211 | Z4: =RESULT!G9 -> The performance is getting better, please keep improve the performance. | AA4: =IF(Y4>4.99,"Exceptional",IF(Y4>3.99,"Exceed Expectation",IF(Y4>=2.99,"Meet Expectation",IF(Y4>1.9,"Below Expectation","Unsatisfactory")))) -> Meet Expectation
A5: INFORMASI TEKNOLOGI INDONESIA | B5: PENYEDIAAN JASA SMS BROADCAST DAN JASA SMS PULL; CONNECTIVITY PRIMARY LINK | C5: 3.78 | D5: =IF(C5>4.99,"Exceptional",IF(C5>3.99,"Exceed Expectation",IF(C5>=2.99,"Meet Expectation",IF(C5>1.9,"Below Expectation","Unsatisfactory")))) -> Meet Expectation | E5: 4.21 | F5: =IF(E5>4.99,"Exceptional",IF(E5>3.99,"Exceed Expectation",IF(E5>=2.99,"Meet Expectation",IF(E5>1.9,"Below Expectation","Unsatisfactory")))) -> Exceed Expectation | G5: 3 | H5: =IF(G5>4.99,"Exceptional",IF(G5>3.99,"Exceed Expectation",IF(G5>=2.99,"Meet Expectation",IF(G5>1.9,"Below Expectation","Unsatisfactory")))) -> Meet Expectation | I5: 3 | J5: =IF(I5>4.99,"Exceptional",IF(I5>3.9,"Exceed Expectation",IF(I5>=2.99,"Meet Expectation",IF(I5>1.9,"Below Expectation","Unsatisfactory")))) -> Meet Expectation | K5: 3 | L5: Sejauh ini untuk Vendor jaris tidak ada kendala, responsif. | M5: =IF(K5>4.99,"Exceptional",IF(K5>3.9,"Exceed Expectation",IF(K5>=2.99,"Meet Expectation",IF(K5>1.9,"Below Expectation","Unsatisfactory")))) -> Meet Expectation | N5: 3 | O5: So far Jatis has provided good service | P5: =IF(N5>4.99,"Exceptional",IF(N5>3.9,"Exceed Expectation",IF(N5>=2.99,"Meet Expectation",IF(N5>1.9,"Below Expectation","Unsatisfactory")))) -> Meet Expectation | Q5: 3 | R5: Secara keseluran service yang diberikan oleh JATIS baik | S5: Meet Expectation | T5: 0x | U5: - | V5: 3.0818182 | W5: STILL MEET REQUIREMENT | X5: MEET EXPECTATION | Y5: =RESULT!E6 -> 3 | Z5: =RESULT!G6 -> Jatis has provided good service throughout this year | AA5: =IF(Y5>4.99,"Exceptional",IF(Y5>3.99,"Exceed Expectation",IF(Y5>=2.99,"Meet Expectation",IF(Y5>1.9,"Below Expectation","Unsatisfactory")))) -> Meet Expectation
A6: MITRA INTEGRASI INFORMATIKA | B6: SFDC MAINTENANCE | C6: 3 | D6: =IF(C6>4.99,"Exceptional",IF(C6>3.99,"Exceed Expectation",IF(C6>=2.99,"Meet Expectation",IF(C6>1.9,"Below Expectation","Unsatisfactory")))) -> Meet Expectation | E6: 3 | F6: =IF(E6>4.99,"Exceptional",IF(E6>3.99,"Exceed Expectation",IF(E6>=2.99,"Meet Expectation",IF(E6>1.9,"Below Expectation","Unsatisfactory")))) -> Meet Expectation | G6: 3.96 | H6: =IF(G6>4.99,"Exceptional",IF(G6>3.99,"Exceed Expectation",IF(G6>=2.99,"Meet Expectation",IF(G6>1.9,"Below Expectation","Unsatisfactory")))) -> Meet Expectation | I6: 3.65 | J6: =IF(I6>4.99,"Exceptional",IF(I6>3.9,"Exceed Expectation",IF(I6>=2.99,"Meet Expectation",IF(I6>1.9,"Below Expectation","Unsatisfactory")))) -> Meet Expectation | K6: 3 | L6: 0 | M6: =IF(K6>4.99,"Exceptional",IF(K6>3.9,"Exceed Expectation",IF(K6>=2.99,"Meet Expectation",IF(K6>1.9,"Below Expectation","Unsatisfactory")))) -> Meet Expectation | N6: 4.4166667 | O6: The response from the MII Team to all the issues and needs we encountered has been quite good. They were able to promptly provide workarounds and broad solutions. The PIC assigned to the project was very communicative and responsible. Please maintain this level of performance, as we truly rely on it. | P6: =IF(N6>4.99,"Exceptional",IF(N6>3.9,"Exceed Expectation",IF(N6>=2.99,"Meet Expectation",IF(N6>1.9,"Below Expectation","Unsatisfactory")))) -> Exceed Expectation | Q6: 4.3538462 | R6: Good for MII, keep it up. | S6: Exceed Expectation | T6: 0x | U6: - | V6: 4.2730769 | W6: OVERALL, THE SUPPORT FROM MII IS VERY GOOD AND VERY HELPFUL, BOTH IN TERMS OF COMMUNICATION AND TECHNICAL ASPECTS, IT IS VERY EASY TO UNDERSTAND. | X6: EXCEED EXPECTATION | Y6: =RESULT!E13 -> 4.8294872 | Z6: =RESULT!G13 -> verall, the level of support has been satisfactory. The improvements carried out were highly effective, and several demands were consistent with the initial assessment and expectations. | AA6: =IF(Y6>4.99,"Exceptional",IF(Y6>3.99,"Exceed Expectation",IF(Y6>=2.99,"Meet Expectation",IF(Y6>1.9,"Below Expectation","Unsatisfactory")))) -> Exceed Expectation
A7: MULTIFILING MITRA INDONESIA | B7: RECORD MANAGEMENT SERVICE | C7: 3 | D7: =IF(C7>4.99,"Exceptional",IF(C7>3.99,"Exceed Expectation",IF(C7>=2.99,"Meet Expectation",IF(C7>1.9,"Below Expectation","Unsatisfactory")))) -> Meet Expectation | E7: 4 | F7: =IF(E7>4.99,"Exceptional",IF(E7>3.99,"Exceed Expectation",IF(E7>=2.99,"Meet Expectation",IF(E7>1.9,"Below Expectation","Unsatisfactory")))) -> Exceed Expectation | G7: 4 | H7: =IF(G7>4.99,"Exceptional",IF(G7>3.99,"Exceed Expectation",IF(G7>=2.99,"Meet Expectation",IF(G7>1.9,"Below Expectation","Unsatisfactory")))) -> Exceed Expectation | I7: 3.65 | J7: =IF(I7>4.99,"Exceptional",IF(I7>3.9,"Exceed Expectation",IF(I7>=2.99,"Meet Expectation",IF(I7>1.9,"Below Expectation","Unsatisfactory")))) -> Meet Expectation | K7: 3 | L7: - | M7: =IF(K7>4.99,"Exceptional",IF(K7>3.9,"Exceed Expectation",IF(K7>=2.99,"Meet Expectation",IF(K7>1.9,"Below Expectation","Unsatisfactory")))) -> Meet Expectation | N7: 3 | O7: overall OK | P7: =IF(N7>4.99,"Exceptional",IF(N7>3.9,"Exceed Expectation",IF(N7>=2.99,"Meet Expectation",IF(N7>1.9,"Below Expectation","Unsatisfactory")))) -> Meet Expectation | Q7: 3.9125 | R7: Untuk project destroy harga jangan mahal mahal | S7: Exceed Expectation | T7: 0x | U7: - | V7: 3.0693182 | W7: INOVASI FROM MMI FOR SIMPLIFY PROCESS STORAGE | X7: MEET EXPECTATION | Y7: =RESULT!E8 -> 3.0318182 | Z7: =RESULT!G8 -> impprove innovation dan simplyfy process | AA7: =IF(Y7>4.99,"Exceptional",IF(Y7>3.99,"Exceed Expectation",IF(Y7>=2.99,"Meet Expectation",IF(Y7>1.9,"Below Expectation","Unsatisfactory")))) -> Meet Expectation
A8: CIPTADRA SOFTINDO | B8: PEMELIHARAAN PERANGKAT LUNAK AXITS DAN PERANGKAT LUNAK DMTM | C8: 4.9 | D8: =IF(C8>4.99,"Exceptional",IF(C8>3.99,"Exceed Expectation",IF(C8>=2.99,"Meet Expectation",IF(C8>1.9,"Below Expectation","Unsatisfactory")))) -> Exceed Expectation | E8: 4.73 | F8: =IF(E8>4.99,"Exceptional",IF(E8>3.99,"Exceed Expectation",IF(E8>=2.99,"Meet Expectation",IF(E8>1.9,"Below Expectation","Unsatisfactory")))) -> Exceed Expectation | G8: 3.38 | H8: =IF(G8>4.99,"Exceptional",IF(G8>3.99,"Exceed Expectation",IF(G8>=2.99,"Meet Expectation",IF(G8>1.9,"Below Expectation","Unsatisfactory")))) -> Meet Expectation | I8: 3 | J8: =IF(I8>4.99,"Exceptional",IF(I8>3.9,"Exceed Expectation",IF(I8>=2.99,"Meet Expectation",IF(I8>1.9,"Below Expectation","Unsatisfactory")))) -> Meet Expectation | K8: 3.975 | L8: Ciptadra saat ini sudah sangat membantu IT AMFS apabila ada Issue atau Problem yang terjadi di DMTM dengan cepat. | M8: =IF(K8>4.99,"Exceptional",IF(K8>3.9,"Exceed Expectation",IF(K8>=2.99,"Meet Expectation",IF(K8>1.9,"Below Expectation","Unsatisfactory")))) -> Exceed Expectation | N8: 3.675 | O8: Ciptadra sudah bekerja dengan baik apabila ada Issue terjadi, sangat fast Response. | P8: =IF(N8>4.99,"Exceptional",IF(N8>3.9,"Exceed Expectation",IF(N8>=2.99,"Meet Expectation",IF(N8>1.9,"Below Expectation","Unsatisfactory")))) -> Meet Expectation | Q8: 3.75 | R8: - | S8: Meet Expectation | T8: 0x | U8: - | V8: 4.2 | W8: - | X8: EXCEED EXPECTATION | Y8: =RESULT!E10 -> 4 | Z8: =RESULT!G10 -> Performance is Good | AA8: =IF(Y8>4.99,"Exceptional",IF(Y8>3.99,"Exceed Expectation",IF(Y8>=2.99,"Meet Expectation",IF(Y8>1.9,"Below Expectation","Unsatisfactory")))) -> Exceed Expectation
A9: INMOTION INOVASI TEKNOLOGI | B9: JASA APLIKASI CHATBOT DAN LIVE CHAT | C9: 3 | D9: =IF(C9>4.99,"Exceptional",IF(C9>3.99,"Exceed Expectation",IF(C9>=2.99,"Meet Expectation",IF(C9>1.9,"Below Expectation","Unsatisfactory")))) -> Meet Expectation | E9: 3 | F9: =IF(E9>4.99,"Exceptional",IF(E9>3.99,"Exceed Expectation",IF(E9>=2.99,"Meet Expectation",IF(E9>1.9,"Below Expectation","Unsatisfactory")))) -> Meet Expectation | G9: 3.09 | H9: =IF(G9>4.99,"Exceptional",IF(G9>3.99,"Exceed Expectation",IF(G9>=2.99,"Meet Expectation",IF(G9>1.9,"Below Expectation","Unsatisfactory")))) -> Meet Expectation | I9: 3 | J9: =IF(I9>4.99,"Exceptional",IF(I9>3.9,"Exceed Expectation",IF(I9>=2.99,"Meet Expectation",IF(I9>1.9,"Below Expectation","Unsatisfactory")))) -> Meet Expectation | K9: 2.121875 | L9: More responsive in solving problems and always providing information on the latest features to support future customer service. | M9: =IF(K9>4.99,"Exceptional",IF(K9>3.9,"Exceed Expectation",IF(K9>=2.99,"Meet Expectation",IF(K9>1.9,"Below Expectation","Unsatisfactory")))) -> Below Expectation | N9: 2.9890625 | O9: Maintain the consistency and communication that has been established. Always take the initiative to provide the latest information regarding developments in the Live Chat service. | P9: =IF(N9>4.99,"Exceptional",IF(N9>3.9,"Exceed Expectation",IF(N9>=2.99,"Meet Expectation",IF(N9>1.9,"Below Expectation","Unsatisfactory")))) -> Below Expectation | Q9: 3 | R9: Tetap selalu berikan Service yang Terbaik | S9: Meet Expectation | T9: 0x | U9: Sudah dilakukan pemanggilan terhadap vendor yang bersangkutan dan pada Q3 terjadi perbaikan performance | V9: 3.65 | W9: - | X9: MEET EXPECTATION | Y9: =RESULT!E12 -> 4 | Z9: =RESULT!G12 -> continue performing thorough and frequent periodic checks to ensure that during service hours, there are no issues that could disrupt operations and resolve the remaining unresolved 401 issue Berikan umpan balik Anda tentang BizChat | AA9: =IF(Y9>4.99,"Exceptional",IF(Y9>3.99,"Exceed Expectation",IF(Y9>=2.99,"Meet Expectation",IF(Y9>1.9,"Below Expectation","Unsatisfactory")))) -> Exceed Expectation
A10: SATRIA ANTARAN PRIMA TBK | B10: PENGIRIMAN POLIS DOKUMEN DAN PAKET DALAM NEGERI | C10: 3.75 | D10: =IF(C10>4.99,"Exceptional",IF(C10>3.99,"Exceed Expectation",IF(C10>=2.99,"Meet Expectation",IF(C10>1.9,"Below Expectation","Unsatisfactory")))) -> Meet Expectation | E10: 3.83 | F10: =IF(E10>4.99,"Exceptional",IF(E10>3.99,"Exceed Expectation",IF(E10>=2.99,"Meet Expectation",IF(E10>1.9,"Below Expectation","Unsatisfactory")))) -> Meet Expectation | G10: 2.74 | H10: =IF(G10>4.99,"Exceptional",IF(G10>3.99,"Exceed Expectation",IF(G10>=2.99,"Meet Expectation",IF(G10>1.9,"Below Expectation","Unsatisfactory")))) -> Below Expectation | I10: 2.725 | J10: =IF(I10>4.99,"Exceptional",IF(I10>3.9,"Exceed Expectation",IF(I10>=2.99,"Meet Expectation",IF(I10>1.9,"Below Expectation","Unsatisfactory")))) -> Below Expectation | K10: 2.86 | L10: User 1: ada progress positif dari SAP untuk memperbaiki apa yang kurang di periode sebelumnya. User 2: late respon terhadap keluhan pickup pengiriman dan validasi pengiriman dari PIC Unie. Draft invoice yang dikirimkan blm tertata dengan baik atau sesuai dengan kesamaan data dari User. | M10: =IF(K10>4.99,"Exceptional",IF(K10>3.9,"Exceed Expectation",IF(K10>=2.99,"Meet Expectation",IF(K10>1.9,"Below Expectation","Unsatisfactory")))) -> Below Expectation | N10: 2.6166667 | O10: - SAP should be improve the quality of its couriers regarding accuracy of delivery status. - komunikasi dgn Unie sangat sulit, slow respons, invoice yg dikirimkan juga tidak ada respon dan updatenya ketika sudah di reminder. pickup dokumen secara manual (tidak menggunakan sistem) masih berjalan dan diterima oleh SAP. | P10: =IF(N10>4.99,"Exceptional",IF(N10>3.9,"Exceed Expectation",IF(N10>=2.99,"Meet Expectation",IF(N10>1.9,"Below Expectation","Unsatisfactory")))) -> Below Expectation | Q10: 2.5 | R10: User 1: invoice periode maret-juni 2025 tdk ada update. update status informasi pengiriman tidak valid (fake shipment), kendala akun tidak dapat melakukan input, pickup manual masih terus berjalan (no commit). dah laah caapee User 2: sudah ada kemajuan mengenai respon terhadap complain handling oleh SAP | S10: Below Expectation | T10: 5X | U10: Pada periode Q2, Business User memberikan konfirmasi bahwa SAP diberi penilaian positif atas adanya perubahan dari proses pickup dokumen dan pengiriman invoice sebagai tanggapan kepada procurement ketika procurement memberikan masukan untuk melakukan penggantian vendor. Pada periode Q3, User kembali memberikan nilai below expectation dan akan dilakukan pemanggilan kepada vendor terkait. Paralel dengan proses tersebut, procurement melakukan arrangement untuk pemilihan vendor alternatif atas kebutuhan courier services. | V10: 2.9611111 | W10: VEMDOR SAP ADA PENINGKATAN TERUTAMA DI KOMUNIKASI PIC NYA | X10: BELOW EXPECTATION | Y10: =RESULT!E7 -> 3 | Z10: =RESULT!G7 -> SAP has provided excellent service throughout this year | AA10: =IF(Y10>4.99,"Exceptional",IF(Y10>3.99,"Exceed Expectation",IF(Y10>=2.99,"Meet Expectation",IF(Y10>1.9,"Below Expectation","Unsatisfactory")))) -> Meet Expectation
A11: SATRIA ANTARAN PRIMA TBK | B11: MAILING ROOM | C11: N/A | D11: N/A | E11: N/A | F11: N/A | G11: N/A | H11: N/A | I11: N/A | J11: N/A | K11: 3 | L11: - | M11: =IF(K11>4.99,"Exceptional",IF(K11>3.9,"Exceed Expectation",IF(K11>=2.99,"Meet Expectation",IF(K11>1.9,"Below Expectation","Unsatisfactory")))) -> Meet Expectation | N11: N/A | O11: N/A | P11: N/A | Q11: 3.9125 | R11: tingkatkan lebih performancenya | S11: Exceed Expectation | T11: 0x | U11: - | V11: 3.05 | W11: NEED INOVATION FROM SAP FOR SIMPLIFY PROCESS AT AXA MANDIRI MAILING ROOM | X11: MEET EXPECTATION | Y11: =RESULT!E5 -> 3.4041667 | Z11: =RESULT!G5 -> Over all mailing ok, please improve coordinated with Headoffice team for reduce complain/misscomm (ex case overseas shipment ) | AA11: =IF(Y11>4.99,"Exceptional",IF(Y11>3.99,"Exceed Expectation",IF(Y11>=2.99,"Meet Expectation",IF(Y11>1.9,"Below Expectation","Unsatisfactory")))) -> Meet Expectation
A12: TARGET SUKSES SINERGI | B12: PENGIRIMAN EMAIL MARKETING AUTOMATION | C12: 2.85 | D12: =IF(C12>4.99,"Exceptional",IF(C12>3.99,"Exceed Expectation",IF(C12>=2.99,"Meet Expectation",IF(C12>1.9,"Below Expectation","Unsatisfactory")))) -> Below Expectation | E12: 3.28 | F12: =IF(E12>4.99,"Exceptional",IF(E12>3.99,"Exceed Expectation",IF(E12>=2.99,"Meet Expectation",IF(E12>1.9,"Below Expectation","Unsatisfactory")))) -> Meet Expectation | G12: 4 | H12: =IF(G12>4.99,"Exceptional",IF(G12>3.99,"Exceed Expectation",IF(G12>=2.99,"Meet Expectation",IF(G12>1.9,"Below Expectation","Unsatisfactory")))) -> Exceed Expectation | I12: 3.3125 | J12: =IF(I12>4.99,"Exceptional",IF(I12>3.9,"Exceed Expectation",IF(I12>=2.99,"Meet Expectation",IF(I12>1.9,"Below Expectation","Unsatisfactory")))) -> Meet Expectation | K12: 3.7444444 | L12: Overall our partnership going well | M12: =IF(K12>4.99,"Exceptional",IF(K12>3.9,"Exceed Expectation",IF(K12>=2.99,"Meet Expectation",IF(K12>1.9,"Below Expectation","Unsatisfactory")))) -> Meet Expectation | N12: 4 | O12: Please keep up the good work! | P12: =IF(N12>4.99,"Exceptional",IF(N12>3.9,"Exceed Expectation",IF(N12>=2.99,"Meet Expectation",IF(N12>1.9,"Below Expectation","Unsatisfactory")))) -> Exceed Expectation | Q12: 3 | R12: Overall Good | S12: Meet Expectation | T12: 0x | U12: - | V12: 3.65 | W12: GOOD | X12: MEET EXPECTATION | Y12: =RESULT!E11 -> 3.9 | Z12: =RESULT!G11 -> Harganya buat next contrac please murahin ya | AA12: =IF(Y12>4.99,"Exceptional",IF(Y12>3.99,"Exceed Expectation",IF(Y12>=2.99,"Meet Expectation",IF(Y12>1.9,"Below Expectation","Unsatisfactory")))) -> Meet Expectation
A13: WIZ TECHNOLOGY INDONESIA | B13: VOICE BOT REMINDER CALL | C13: 3 | D13: =IF(C13>4.99,"Exceptional",IF(C13>3.99,"Exceed Expectation",IF(C13>=2.99,"Meet Expectation",IF(C13>1.9,"Below Expectation","Unsatisfactory")))) -> Meet Expectation | E13: 3.61 | F13: =IF(E13>4.99,"Exceptional",IF(E13>3.99,"Exceed Expectation",IF(E13>=2.99,"Meet Expectation",IF(E13>1.9,"Below Expectation","Unsatisfactory")))) -> Meet Expectation | G13: 3.4 | H13: =IF(G13>4.99,"Exceptional",IF(G13>3.99,"Exceed Expectation",IF(G13>=2.99,"Meet Expectation",IF(G13>1.9,"Below Expectation","Unsatisfactory")))) -> Meet Expectation | I13: 3.0875 | J13: =IF(I13>4.99,"Exceptional",IF(I13>3.9,"Exceed Expectation",IF(I13>=2.99,"Meet Expectation",IF(I13>1.9,"Below Expectation","Unsatisfactory")))) -> Meet Expectation | K13: 3.0388889 | L13: so far wiz.AI sudah memenuhi apa yang menjadi kebutuhan kami | M13: =IF(K13>4.99,"Exceptional",IF(K13>3.9,"Exceed Expectation",IF(K13>=2.99,"Meet Expectation",IF(K13>1.9,"Below Expectation","Unsatisfactory")))) -> Meet Expectation | N13: 3.5444444 | O13: needs better communication for quicker responses. | P13: =IF(N13>4.99,"Exceptional",IF(N13>3.9,"Exceed Expectation",IF(N13>=2.99,"Meet Expectation",IF(N13>1.9,"Below Expectation","Unsatisfactory")))) -> Meet Expectation | Q13: 3 | R13: sudah baik | S13: Meet Expectation | T13: 0x | U13: - | V13: 3.46875 | W13: WE EXPECT INITIATIVE TO BE TAKEN IN IMPLEMENTING MITIGATION MEASURES AND IN ACCELERATING THE PROCESS WITHIN COLLABORATION WITH WIZ AI. | X13: MEET EXPECTATION | Y13: 0 | Z13: 0
A14: KARYAPUTRA SURYAGEMILANG | B14: TELEMARKETING REVAMP PROJECT | C14: 3.46 | D14: =IF(C14>4.99,"Exceptional",IF(C14>3.99,"Exceed Expectation",IF(C14>=2.99,"Meet Expectation",IF(C14>1.9,"Below Expectation","Unsatisfactory")))) -> Meet Expectation | E14: 3.46 | F14: =IF(E14>4.99,"Exceptional",IF(E14>3.99,"Exceed Expectation",IF(E14>=2.99,"Meet Expectation",IF(E14>1.9,"Below Expectation","Unsatisfactory")))) -> Meet Expectation | G14: 3.86 | H14: =IF(G14>4.99,"Exceptional",IF(G14>3.99,"Exceed Expectation",IF(G14>=2.99,"Meet Expectation",IF(G14>1.9,"Below Expectation","Unsatisfactory")))) -> Meet Expectation | I14: 3 | J14: =IF(I14>4.99,"Exceptional",IF(I14>3.9,"Exceed Expectation",IF(I14>=2.99,"Meet Expectation",IF(I14>1.9,"Below Expectation","Unsatisfactory")))) -> Meet Expectation | K14: 3.1807692 | L14: Need to speed up the investigation and fixing process when issues arise. | M14: =IF(K14>4.99,"Exceptional",IF(K14>3.9,"Exceed Expectation",IF(K14>=2.99,"Meet Expectation",IF(K14>1.9,"Below Expectation","Unsatisfactory")))) -> Meet Expectation | N14: 2.9371795 | O14: As we have many projects involved KPSG in AMFS, please do maintain the dedicated team for TM Revamp. Currently activities in other projects may impact in TM Revamp project, i.e. PureCloud Decommissioned impact in TM Revamp activities (huddle meeting) and deliverables (CRs). We believe each project has different urgency and separate budget which need to be considered not impacted each other. | P14: =IF(N14>4.99,"Exceptional",IF(N14>3.9,"Exceed Expectation",IF(N14>=2.99,"Meet Expectation",IF(N14>1.9,"Below Expectation","Unsatisfactory")))) -> Below Expectation | Q14: 2.4272727 | R14: We concenrn about human resource, somehow we need extra effort time to make Change Request, Assesment Scope and issue. It takes long time to asses new Change Request because availibility human resources. | S14: Below Expectation | T14: 2x | U14: Pada periode Q2 mendapatkan hasil below expectation dan procurement sudah lakukan pemanggilan untuk menyampaikan evaluasi performance tersebut bersama sama dengan business user. Pada periode Q3, business user menyampaikan concern kembali dengan hasil below expectation, dan akan dilakukan pemanggilan kembali kepada KPSG. | V14: 3.5181818 | W14: PLEASE BE MORE PERFORMED BECAUSE OUR NEEDS IS SO FAST FOR STRATEGIC DELIVERY | X14: MEET EXPECTATION | Y14: =RESULT!E19 -> 3.0318182 | Z14: =RESULT!G19 -> Diharapkan untuk tim project yang diassign apabila CR sudah di signoff agar availibility dari resource ready | AA14: =IF(Y14>4.99,"Exceptional",IF(Y14>3.99,"Exceed Expectation",IF(Y14>=2.99,"Meet Expectation",IF(Y14>1.9,"Below Expectation","Unsatisfactory")))) -> Meet Expectation
A15: ARAH SEJAHTERA ABADI | B15: PERJANJIAN SEWA MENYEWA | C15: N/A | D15: N/A | E15: 3 | F15: =IF(E15>4.99,"Exceptional",IF(E15>3.99,"Exceed Expectation",IF(E15>=2.99,"Meet Expectation",IF(E15>1.9,"Below Expectation","Unsatisfactory")))) -> Meet Expectation | G15: 3 | H15: =IF(G15>4.99,"Exceptional",IF(G15>3.99,"Exceed Expectation",IF(G15>=2.99,"Meet Expectation",IF(G15>1.9,"Below Expectation","Unsatisfactory")))) -> Meet Expectation | I15: 3.35 | J15: =IF(I15>4.99,"Exceptional",IF(I15>3.9,"Exceed Expectation",IF(I15>=2.99,"Meet Expectation",IF(I15>1.9,"Below Expectation","Unsatisfactory")))) -> Meet Expectation | K15: 2.8409091 | L15: Improve Resolution repair, for this year resolution fro problem dusty and project smell CCC impact project from another tenant behind CCC GF ( NOV 2024 until now still not yet solution ) | M15: =IF(K15>4.99,"Exceptional",IF(K15>3.9,"Exceed Expectation",IF(K15>=2.99,"Meet Expectation",IF(K15>1.9,"Below Expectation","Unsatisfactory")))) -> Below Expectation | N15: 2.7727273 | O15: for improvment is Improve resolusi repair/corective device Building in tenant area | P15: =IF(N15>4.99,"Exceptional",IF(N15>3.9,"Exceed Expectation",IF(N15>=2.99,"Meet Expectation",IF(N15>1.9,"Below Expectation","Unsatisfactory")))) -> Below Expectation | Q15: 2 | R15: adanya SLA atau KPI utuk review kuncit | S15: Below Expectation | T15: 3x | U15: Pada periode Q1, Q2, dan Q3, hasil penilaian evaluasinya cenderung turun karena dari pihak Kuningan City tidak bersedia dianggap sebagai vendor / supplier, yang bisa diberlakukan penilaian performance atas layanan yang diberikan. Dari sisi operasional, memberikan nilai below expectation karena pihak Kuncit dirasa kurang responsif dalam menanggapi keluhan. | V15: 2.9611111 | W15: KUNCIT SUPPORT FOR SPACE AMFS (GIVE MORE ADVANTAGE FREE CHARGE FOR 12), FOR THE REPAIR /SOLUTION NEED MORE IMPROVE TIME OR QUALITY | X15: BELOW EXPECTATION | Y15: =RESULT!E16 -> 2.9611111 | Z15: =RESULT!G16 -> Improve quality service, specially for leakage, | AA15: =IF(Y15>4.99,"Exceptional",IF(Y15>3.99,"Exceed Expectation",IF(Y15>=2.99,"Meet Expectation",IF(Y15>1.9,"Below Expectation","Unsatisfactory")))) -> Below Expectation
A16: DELOITTE CONSULTING | B16: DATA PRIVACY TOOLS & PELATIHAN PERSONAL DATA PROTECTION (PDP) | C16: N/A | D16: N/A | E16: N/A | F16: N/A | G16: N/A | H16: N/A | I16: 3.2333333 | J16: =IF(I16>4.99,"Exceptional",IF(I16>3.9,"Exceed Expectation",IF(I16>=2.99,"Meet Expectation",IF(I16>1.9,"Below Expectation","Unsatisfactory")))) -> Meet Expectation | K16: 2.9708333 | L16: They need to deepen their product knowledge so that they can be right on target in providing solutions. | M16: =IF(K16>4.99,"Exceptional",IF(K16>3.9,"Exceed Expectation",IF(K16>=2.99,"Meet Expectation",IF(K16>1.9,"Below Expectation","Unsatisfactory")))) -> Below Expectation | N16: 2.8833333 | O16: Understand more about product feature knowledge so that vendors can explain accurately and convincingly when there is trouble or product limitations. | P16: =IF(N16>4.99,"Exceptional",IF(N16>3.9,"Exceed Expectation",IF(N16>=2.99,"Meet Expectation",IF(N16>1.9,"Below Expectation","Unsatisfactory")))) -> Below Expectation | Q16: 3.1 | R16: More coordination with PIC Principal Product (Securiti.ai) to get information regarding product updates earlier. | S16: Meet Expectation | T16: 0x | U16: - | V16: 3.1166667 | W16: MORE COORDINATION WITH PIC PRINCIPAL PRODUCT (SECURITI.AI) TO GET INFORMATION REGARDING PRODUCT UPDATES EARLIER. | X16: MEET EXPECTATION | Y16: =RESULT!E17 -> 3.1636364 | Z16: =RESULT!G17 -> Need more improvement regarding initiative to take mitigation/preventive action to prevent the problem from recurring/current issue. | AA16: =IF(Y16>4.99,"Exceptional",IF(Y16>3.99,"Exceed Expectation",IF(Y16>=2.99,"Meet Expectation",IF(Y16>1.9,"Below Expectation","Unsatisfactory")))) -> Meet Expectation
